<?xml version="1.0" encoding="utf-8"?>
<!--
This URDF was automatically created by SolidWorks to URDF Exporter! Originally created by Stephen Brawner (brawner@gmail.com)
Commit Version: 1.6.0-4-g7f85cfe  Build Version: 1.6.7995.38578
For more information, please see http://wiki.ros.org/sw_urdf_exporter
-->
<robot name="hi_1_18_240815">
	<link name="base_link">
		<inertial>
			<origin xyz="-9.6590197018076E-05 2.66945392179974E-09 0.017511404414247" rpy="0 0 0" />
			<mass value="0.219640722451849" />
			<inertia ixx="9.7527390976077E-05" ixy="-2.49731365889959E-13" ixz="-2.33467801644995E-08" iyy="4.60993568895392E-05" iyz="-6.31467170287875E-15" izz="0.000131926303651487" />
		</inertial>
		<visual>
			<origin xyz="0 0 0" rpy="0 0 0" />
			<geometry>
				<mesh filename="package://hi_1_18_240815/meshes/base_link.STL" />
			</geometry>
			<material name="">
				<color rgba="0.898039215686275 0.917647058823529 0.929411764705882 1" />
			</material>
		</visual>
		<collision>
			<origin xyz="0 0 0" rpy="0 0 0" />
			<geometry>
				<mesh filename="package://hi_1_18_240815/meshes/base_link.STL" />
			</geometry>
		</collision>
	</link>
  <!-- right leg -->
	<link name="r_hip_yaw_link">
		<inertial>
			<origin xyz="-0.0452945773118738 8.81715097111602E-05 -0.0415560509674436" rpy="0 0 0" />
			<mass value="0.120408658433537" />
			<inertia ixx="4.11024304540314E-05" ixy="-1.17241833095431E-08" ixz="7.32862007183345E-07" iyy="2.69917328362111E-05" iyz="2.03837278278495E-07" izz="2.98073392159216E-05" />
		</inertial>
		<visual>
			<origin xyz="0 0 0" rpy="0 0 0" />
			<geometry>
				<mesh filename="package://hi_1_18_240815/meshes/r_hip_yaw_link.STL" />
			</geometry>
			<material name="">
				<color rgba="0.898039215686275 0.917647058823529 0.929411764705882 1" />
			</material>
		</visual>
		<collision>
			<origin xyz="0 0 -0.01" rpy="0 0 0" />
			<geometry>
				<box size="0.01 0.01 0.01" />
			</geometry>
		</collision>
	</link>
	<joint name="r_hip_yaw_joint" type="revolute">
		<origin xyz="0 -0.0750000000000002 0" rpy="0 0 0" />
		<parent link="base_link" />
		<child link="r_hip_yaw_link" />
		<axis xyz="0 0 1" />
		<limit lower="-0.6" upper="0.6" effort="21" velocity="15" />
	</joint>
	<link name="r_hip_roll_link">
		<inertial>
			<origin xyz="-0.00585514226993999 0.000707913786671677 -0.000520393992596097" rpy="0 0 0" />
			<mass value="0.216049524730802" />
			<inertia ixx="5.82099492702052E-05" ixy="7.54668754162213E-07" ixz="6.8571890279089E-07" iyy="7.98066439527875E-05" iyz="6.12044500417285E-07" izz="5.28889818390366E-05" />
		</inertial>
		<visual>
			<origin xyz="0 0 0" rpy="0 0 0" />
			<geometry>
				<mesh filename="package://hi_1_18_240815/meshes/r_hip_roll_link.STL" />
			</geometry>
			<material name="">
				<color rgba="0.898039215686275 0.917647058823529 0.929411764705882 1" />
			</material>
		</visual>
		<collision>
			<origin xyz="-0.03 0 0" rpy="0 0 0" />
			<geometry>
				<box size="0.01 0.01 0.01" />
			</geometry>
		</collision>
	</link>
	<joint name="r_hip_roll_joint" type="revolute">
		<origin xyz="0 0 -0.059" rpy="0 0 0" />
		<parent link="r_hip_yaw_link" />
		<child link="r_hip_roll_link" />
		<axis xyz="1 0 0" />
		<limit lower="-0.4" upper="0.22" effort="21" velocity="15" />
	</joint>
	<link name="r_thigh_link">
		<inertial>
			<origin xyz="0.00103801707041157 -0.000603161704391009 -0.0838693764326068" rpy="0 0 0" />
			<mass value="0.169091271696126" />
			<inertia ixx="0.000355117443370859" ixy="-9.01629128908972E-11" ixz="8.36208801999528E-06" iyy="0.000362770214304677" iyz="-4.13355953552034E-08" izz="1.21701792916971E-05" />
		</inertial>
		<visual>
			<origin xyz="0 0 0" rpy="0 0 0" />
			<geometry>
				<mesh filename="package://hi_1_18_240815/meshes/r_thigh_link.STL" />
			</geometry>
			<material name="">
				<color rgba="0.898039215686275 0.917647058823529 0.929411764705882 1" />
			</material>
		</visual>
		<collision>
			<origin xyz="0 0 -0.075" rpy="0 -0.05009 0" />
			<geometry>
				<box size="0.02 0.02 0.12" />
			</geometry>
		</collision>
	</link>
	<joint name="r_thigh_joint" type="revolute">
		<origin xyz="0 0 0" rpy="0 0 0" />
		<parent link="r_hip_roll_link" />
		<child link="r_thigh_link" />
		<axis xyz="0 1 0" />
		<limit lower="-2.25" upper="0.4" effort="21" velocity="15" />
	</joint>
	<link name="r_calf_link">
		<inertial>
			<origin xyz="0.00341568016745786 9.14311076849472E-09 -0.0862881016500004" rpy="0 0 0" />
			<mass value="0.345864574670698" />
			<inertia ixx="0.00010131115734342" ixy="-2.06713733285833E-10" ixz="-9.41534517766059E-07" iyy="0.000130660154686472" iyz="3.87925888041405E-08" izz="5.93607176151694E-05" />
		</inertial>
		<visual>
			<origin xyz="0 0 0" rpy="0 0 0" />
			<geometry>
				<mesh filename="package://hi_1_18_240815/meshes/r_calf_link.STL" />
			</geometry>
			<material name="">
				<color rgba="0.898039215686275 0.917647058823529 0.929411764705882 1" />
			</material>
		</visual>
		<collision>
			<origin xyz="0 0 -0.075" rpy="0 0 0" />
			<geometry>
				<box size="0.03 0.035 0.12" />
			</geometry>
		</collision>
	</link>
	<joint name="r_calf_joint" type="revolute">
		<origin xyz="0 0 -0.15" rpy="0 0 0" />
		<parent link="r_thigh_link" />
		<child link="r_calf_link" />
		<axis xyz="0 1 0" />
		<limit lower="0.0" upper="2.37" effort="21" velocity="15" />
	</joint>
	<link name="r_ankle_pitch_link">
		<inertial>
			<origin xyz="-1.42070857855892E-08 8.21263110295511E-09 -4.70824490506061E-11" rpy="0 0 0" />
			<mass value="0.0115843691950255" />
			<inertia ixx="2.75883933430468E-07" ixy="5.81381572917169E-15" ixz="1.41926800526937E-12" iyy="1.11899769215908E-06" iyz="1.67197360549161E-13" izz="1.03965074716124E-06" />
		</inertial>
		<visual>
			<origin xyz="0 0 0" rpy="0 0 0" />
			<geometry>
				<mesh filename="package://hi_1_18_240815/meshes/r_ankle_pitch_link.STL" />
			</geometry>
			<material name="">
				<color rgba="0.650980392156863 0.619607843137255 0.588235294117647 1" />
			</material>
		</visual>
		<collision>
			<origin xyz="0 0 0" rpy="0 0 0" />
			<geometry>
				<mesh filename="package://hi_1_18_240815/meshes/r_ankle_pitch_link.STL" />
			</geometry>
		</collision>
	</link>
	<joint name="r_ankle_pitch_joint" type="revolute">
		<origin xyz="0 0 -0.175449999999999" rpy="0 0 0" />
		<parent link="r_calf_link" />
		<child link="r_ankle_pitch_link" />
		<axis xyz="0 1 0" />
		<limit lower="-0.83" upper="0.59" effort="21" velocity="15" />
	</joint>
	<link name="r_ankle_roll_link">
		<inertial>
			<origin xyz="0.0170975854819203 2.18025711873349E-07 -0.021695426745728" rpy="0 0 0" />
			<mass value="0.258817325242768" />
			<inertia ixx="8.64990486695615E-05" ixy="8.64833602408428E-10" ixz="-2.04033925096855E-08" iyy="0.000308957001898263" iyz="-6.42479544638428E-10" izz="0.000388373719804448" />
		</inertial>
		<visual>
			<origin xyz="0 0 0" rpy="0 0 0" />
			<geometry>
				<mesh filename="package://hi_1_18_240815/meshes/r_ankle_roll_link.STL" />
			</geometry>
			<material name="">
				<color rgba="0.898039215686275 0.917647058823529 0.929411764705882 1" />
			</material>
		</visual>
		<collision>
			<origin xyz="0 0 0" rpy="0 0 0" />
			<geometry>
				<mesh filename="package://hi_1_18_240815/meshes/r_ankle_roll_link.STL" />
			</geometry>
		</collision>
	</link>
	<joint name="r_ankle_roll_joint" type="fixed">
		<origin xyz="0 0 0" rpy="0 0 0" />
		<parent link="r_ankle_pitch_link" />
		<child link="r_ankle_roll_link" />
		<axis xyz="1 0 0" />
		<limit lower="-0.4" upper="0.4" effort="21" velocity="15" />
	</joint>
  <!-- left leg -->
	<link name="l_hip_yaw_link">
		<inertial>
			<origin xyz="-0.0452945783419357 -8.81718843534737E-05 -0.0415560520151556" rpy="0 0 0" />
			<mass value="0.120408666428651" />
			<inertia ixx="4.11024343536449E-05" ixy="1.172450759819E-08" ixz="7.32862090013273E-07" iyy="2.69917353243841E-05" iyz="-2.0383741804376E-07" izz="2.98073415846644E-05" />
		</inertial>
		<visual>
			<origin xyz="0 0 0" rpy="0 0 0" />
			<geometry>
				<mesh filename="package://hi_1_18_240815/meshes/l_hip_yaw_link.STL" />
			</geometry>
			<material name="">
				<color rgba="0.898039215686275 0.917647058823529 0.929411764705882 1" />
			</material>
		</visual>
		<collision>
			<origin xyz="0 0 -0.01" rpy="0 0 0" />
			<geometry>
				<box size="0.01 0.01 0.01" />
			</geometry>
		</collision>
	</link>
	<joint name="l_hip_yaw_joint" type="revolute">
		<origin xyz="0 0.075 0" rpy="0 0 0" />
		<parent link="base_link" />
		<child link="l_hip_yaw_link" />
		<axis xyz="0 0 1" />
		<limit lower="-0.6" upper="0.6" effort="21" velocity="15" />
	</joint>
	<link name="l_hip_roll_link">
		<inertial>
			<origin xyz="-0.00585514195982811 -0.000707913734277755 -0.000520393954080711" rpy="0 0 0" />
			<mass value="0.21604954072103" />
			<inertia ixx="5.82099538295001E-05" ixy="-7.54668754162198E-07" ixz="6.85718902790881E-07" iyy="7.98066515738237E-05" iyz="-6.12044407775941E-07" izz="5.2888986458804E-05" />
		</inertial>
		<visual>
			<origin xyz="0 0 0" rpy="0 0 0" />
			<geometry>
				<mesh filename="package://hi_1_18_240815/meshes/l_hip_roll_link.STL" />
			</geometry>
			<material name="">
				<color rgba="1 1 1 1" />
			</material>
		</visual>
		<collision>
			<origin xyz="-0.03 0 0" rpy="0 0 0" />
			<geometry>
				<box size="0.01 0.01 0.01" />
			</geometry>
		</collision>
	</link>
	<joint name="l_hip_roll_joint" type="revolute">
		<origin xyz="0 0 -0.0590000000000001" rpy="0 0 0" />
		<parent link="l_hip_yaw_link" />
		<child link="l_hip_roll_link" />
		<axis xyz="1 0 0" />
		<limit lower="-0.22" upper="0.4" effort="21" velocity="15" />
	</joint>
	<link name="l_thigh_link">
		<inertial>
			<origin xyz="0.00123405264082221 0.000430789183891705 -0.0803449387076524" rpy="0 0 0" />
			<mass value="0.167652016790401" />
			<inertia ixx="0.000355529853764871" ixy="9.00173981645346E-11" ixz="8.36208812608463E-06" iyy="0.000363827137759541" iyz="4.13354397598421E-08" izz="1.25825954316909E-05" />
		</inertial>
		<visual>
			<origin xyz="0 0 0" rpy="0 0 0" />
			<geometry>
				<mesh filename="package://hi_1_18_240815/meshes/l_thigh_link.STL" />
			</geometry>
			<material name="">
				<color rgba="0.898039215686275 0.917647058823529 0.929411764705882 1" />
			</material>
		</visual>
		<collision>
			<origin xyz="0 0 -0.075" rpy="0 -0.05009 0" />
			<geometry>
				<box size="0.02 0.02 0.12" />
			</geometry>
		</collision>
	</link>
	<joint name="l_thigh_joint" type="revolute">
		<origin xyz="0 0 0" rpy="0 0 0" />
		<parent link="l_hip_roll_link" />
		<child link="l_thigh_link" />
		<axis xyz="0 1 0" />
		<limit lower="-2.25" upper="0.4" effort="21" velocity="15" />
	</joint>
	<link name="l_calf_link">
		<inertial>
			<origin xyz="0.00603806536880236 1.1067721609147E-08 -0.0851876578495915" rpy="0 0 0" />
			<mass value="0.210522555930595" />
			<inertia ixx="7.71381681135475E-05" ixy="1.75972376440046E-10" ixz="-9.41535833469971E-07" iyy="8.86948275382493E-05" iyz="-1.37150877044203E-08" izz="3.47789144460129E-05" />
		</inertial>
		<visual>
			<origin xyz="0 0 0" rpy="0 0 0" />
			<geometry>
				<mesh filename="package://hi_1_18_240815/meshes/l_calf_link.STL" />
			</geometry>
			<material name="">
				<color rgba="0.898039215686275 0.917647058823529 0.929411764705882 1" />
			</material>
		</visual>
		<collision>
			<origin xyz="0 0 -0.075" rpy="0 0 0" />
			<geometry>
				<box size="0.03 0.035 0.12" />
			</geometry>
		</collision>
	</link>
	<joint name="l_calf_joint" type="revolute">
		<origin xyz="0 0 -0.15" rpy="0 0 0" />
		<parent link="l_thigh_link" />
		<child link="l_calf_link" />
		<axis xyz="0 1 0" />
		<limit lower="0.0" upper="2.37" effort="21" velocity="15" />
	</joint>
	<link name="l_ankle_pitch_link">
		<inertial>
			<origin xyz="-8.97068586080962E-09 -4.17038378743712E-09 -6.00226535141246E-11" rpy="0 0 0" />
			<mass value="0.0115843686216336" />
			<inertia ixx="2.75883709657949E-07" ixy="-2.33813706539701E-15" ixz="-7.64711796946902E-13" iyy="1.11899819781407E-06" iyz="-2.69850262825152E-13" izz="1.03965015058698E-06" />
		</inertial>
		<visual>
			<origin xyz="0 0 0" rpy="0 0 0" />
			<geometry>
				<mesh filename="package://hi_1_18_240815/meshes/l_ankle_pitch_link.STL" />
			</geometry>
			<material name="">
				<color rgba="0.898039215686275 0.917647058823529 0.929411764705882 1" />
			</material>
		</visual>
		<collision>
			<origin xyz="0 0 0" rpy="0 0 0" />
			<geometry>
				<mesh filename="package://hi_1_18_240815/meshes/l_ankle_pitch_link.STL" />
			</geometry>
		</collision>
	</link>
	<joint name="l_ankle_pitch_joint" type="revolute">
		<origin xyz="0 0 -0.17545" rpy="0 0 0" />
		<parent link="l_calf_link" />
		<child link="l_ankle_pitch_link" />
		<axis xyz="0 1 0" />
		<limit lower="-0.83" upper="0.59" effort="21" velocity="15" />
	</joint>
	<link name="l_ankle_roll_link">
		<inertial>
			<origin xyz="0.0170012753024263 9.24213320449216E-08 -0.0213352314227333" rpy="0 0 0" />
			<mass value="0.263187944972076" />
			<inertia ixx="8.70942598833061E-05" ixy="5.35817768764779E-09" ixz="-2.08653569188079E-08" iyy="0.00030893332186593" iyz="1.66484635330314E-09" izz="0.000389006984263047" />
		</inertial>
		<visual>
			<origin xyz="0 0 0" rpy="0 0 0" />
			<geometry>
				<mesh filename="package://hi_1_18_240815/meshes/l_ankle_roll_link.STL" />
			</geometry>
			<material name="">
				<color rgba="0.898039215686275 0.917647058823529 0.929411764705882 1" />
			</material>
		</visual>
		<collision>
			<origin xyz="0 0 0" rpy="0 0 0" />
			<geometry>
				<mesh filename="package://hi_1_18_240815/meshes/l_ankle_roll_link.STL" />
			</geometry>
		</collision>
	</link>
	<joint name="l_ankle_roll_joint" type="fixed">
		<origin xyz="0 0 0" rpy="0 0 0" />
		<parent link="l_ankle_pitch_link" />
		<child link="l_ankle_roll_link" />
		<axis xyz="1 0 0" />
		<limit lower="-0.4" upper="0.4" effort="21" velocity="15" />
	</joint>
  <!-- waist -->
	<link name="waist_yaw_link">
		<inertial>
			<origin xyz="-0.00801749794933299 1.56379689677938E-05 0.120489586553777" rpy="0 0 0" />
			<mass value="0.827144549525901" />
			<inertia ixx="0.000844893055492512" ixy="-4.11101467797504E-07" ixz="-2.3493795702939E-05" iyy="0.000855143853529398" iyz="-3.04311926851101E-08" izz="0.00105579045085313" />
		</inertial>
		<visual>
			<origin xyz="0 0 0" rpy="0 0 0" />
			<geometry>
				<mesh filename="package://hi_1_18_240815/meshes/waist_yaw_link.STL" />
			</geometry>
			<material name="">
				<color rgba="1 1 1 1" />
			</material>
		</visual>
		<collision>
			<origin xyz="0 0 0" rpy="0 0 0" />
			<geometry>
				<mesh filename="package://hi_1_18_240815/meshes/waist_yaw_link.STL" />
			</geometry>
		</collision>
	</link>
	<joint name="waist_yaw_joint" type="fixed">
		<origin xyz="0 0 0.0160999999999999" rpy="0 0 0" />
		<parent link="base_link" />
		<child link="waist_yaw_link" />
		<axis xyz="0 0 -1" />
		<limit lower="-3.14" upper="3.14" effort="21" velocity="21" />
	</joint>
  <!-- right arm -->
	<link name="r_shoulder_pitch_link">
		<inertial>
			<origin xyz="0.0068657712811615 -0.0380566814073128 -7.42323545903506E-05" rpy="0 0 0" />
			<mass value="0.0712443976672476" />
			<inertia ixx="2.43873786955946E-05" ixy="-9.71512176136867E-08" ixz="-1.28561573194248E-09" iyy="1.16226166726758E-05" iyz="-8.50161543053269E-08" izz="1.66889386019452E-05" />
		</inertial>
		<visual>
			<origin xyz="0 0 0" rpy="0 0 0" />
			<geometry>
				<mesh filename="package://hi_1_18_240815/meshes/r_shoulder_pitch_link.STL" />
			</geometry>
			<material name="">
				<color rgba="0.898039215686275 0.917647058823529 0.929411764705882 1" />
			</material>
		</visual>
		<collision>
			<origin xyz="0 0 0" rpy="0 0 0" />
			<geometry>
				<mesh filename="package://hi_1_18_240815/meshes/r_shoulder_pitch_link.STL" />
			</geometry>
		</collision>
	</link>
	<joint name="r_shoulder_pitch_joint" type="fixed">
		<origin xyz="0 -0.103 0.219" rpy="0 0 0" />
		<parent link="waist_yaw_link" />
		<child link="r_shoulder_pitch_link" />
		<axis xyz="0 -1 0" />
		<limit lower="-3.14" upper="3.14" effort="21" velocity="21" />
	</joint>
	<link name="r_shoulder_roll_link">
		<inertial>
			<origin xyz="0.0130361958053323 0.000693620998688166 -0.0440802182027369" rpy="0 0 0" />
			<mass value="0.0691228917121305" />
			<inertia ixx="1.49102540341485E-05" ixy="8.50173004146101E-08" ixz="4.64703001200779E-07" iyy="1.45677733849532E-05" iyz="1.4163328004009E-08" izz="1.81326484050293E-05" />
		</inertial>
		<visual>
			<origin xyz="0 0 0" rpy="0 0 0" />
			<geometry>
				<mesh filename="package://hi_1_18_240815/meshes/r_shoulder_roll_link.STL" />
			</geometry>
			<material name="">
				<color rgba="0.898039215686275 0.917647058823529 0.929411764705882 1" />
			</material>
		</visual>
		<collision>
			<origin xyz="0 0 0" rpy="0 0 0" />
			<geometry>
				<mesh filename="package://hi_1_18_240815/meshes/r_shoulder_roll_link.STL" />
			</geometry>
		</collision>
	</link>
	<joint name="r_shoulder_roll_joint" type="fixed">
		<origin xyz="-0.0234000000000001 -0.0509999999999994 0" rpy="0 0 0" />
		<parent link="r_shoulder_pitch_link" />
		<child link="r_shoulder_roll_link" />
		<axis xyz="-1 0 0" />
		<limit lower="-3.14" upper="3.14" effort="21" velocity="21" />
	</joint>
	<link name="r_elbow_yaw_link">
		<inertial>
			<origin xyz="-0.00724259953093076 0.000688729107861163 -0.037919642869774" rpy="0 0 0" />
			<mass value="0.0712443976672479" />
			<inertia ixx="2.43873786955947E-05" ixy="1.28561573195559E-09" ixz="9.71512176137019E-08" iyy="1.66889386019451E-05" iyz="-8.50161543051639E-08" izz="1.16226166726758E-05" />
		</inertial>
		<visual>
			<origin xyz="0 0 0" rpy="0 0 0" />
			<geometry>
				<mesh filename="package://hi_1_18_240815/meshes/r_elbow_yaw_link.STL" />
			</geometry>
			<material name="">
				<color rgba="0.898039215686275 0.917647058823529 0.929411764705882 1" />
			</material>
		</visual>
		<collision>
			<origin xyz="0 0 0" rpy="0 0 0" />
			<geometry>
				<mesh filename="package://hi_1_18_240815/meshes/r_elbow_yaw_link.STL" />
			</geometry>
		</collision>
	</link>
	<joint name="r_elbow_yaw_joint" type="fixed">
		<origin xyz="0.0234000000000034 0 -0.0867000000000017" rpy="0 0 0" />
		<parent link="r_shoulder_roll_link" />
		<child link="r_elbow_yaw_link" />
		<axis xyz="0 0 1" />
		<limit lower="-3.14" upper="3.14" effort="21" velocity="21" />
	</joint>
	<link name="r_elbow_roll_link">
		<inertial>
			<origin xyz="-0.0119831807099061 0.00265820389738827 -0.044080218202726" rpy="0 0 0" />
			<mass value="0.0691228917121347" />
			<inertia ixx="1.49102540341496E-05" ixy="8.50173004146658E-08" ixz="-4.6213198833829E-07" iyy="1.45677733849541E-05" iyz="1.42123695027543E-08" izz="1.81326484050313E-05" />
		</inertial>
		<visual>
			<origin xyz="0 0 0" rpy="0 0 0" />
			<geometry>
				<mesh filename="package://hi_1_18_240815/meshes/r_elbow_roll_link.STL" />
			</geometry>
			<material name="">
				<color rgba="0.898039215686275 0.917647058823529 0.929411764705882 1" />
			</material>
		</visual>
		<collision>
			<origin xyz="0 0 0" rpy="0 0 0" />
			<geometry>
				<mesh filename="package://hi_1_18_240815/meshes/r_elbow_roll_link.STL" />
			</geometry>
		</collision>
	</link>
	<joint name="r_elbow_roll_joint" type="fixed">
		<origin xyz="0.0224999999999939 0 -0.0501000000000089" rpy="0 0 0" />
		<parent link="r_elbow_yaw_link" />
		<child link="r_elbow_roll_link" />
		<axis xyz="1 0 0" />
		<limit lower="-3.14" upper="3.14" effort="21" velocity="21" />
	</joint>
  <!-- left arm -->
	<link name="l_shoulder_pitch_link">
		<inertial>
			<origin xyz="0.00747902477557449 0.0464752115486745 -9.18772432837445E-05" rpy="0 0 0" />
			<mass value="0.0575605049173681" />
			<inertia ixx="2.3332902294842E-05" ixy="-5.30099448381629E-08" ixz="-1.28577570620178E-09" iyy="9.63572325842235E-06" iyz="8.50114887284235E-08" izz="1.55822771109857E-05" />
		</inertial>
		<visual>
			<origin xyz="0 0 0" rpy="0 0 0" />
			<geometry>
				<mesh filename="package://hi_1_18_240815/meshes/l_shoulder_pitch_link.STL" />
			</geometry>
			<material name="">
				<color rgba="0.898039215686275 0.917647058823529 0.929411764705882 1" />
			</material>
		</visual>
		<collision>
			<origin xyz="0 0 0" rpy="0 0 0" />
			<geometry>
				<mesh filename="package://hi_1_18_240815/meshes/l_shoulder_pitch_link.STL" />
			</geometry>
		</collision>
	</link>
	<joint name="l_shoulder_pitch_joint" type="fixed">
		<origin xyz="0 0.103 0.219" rpy="0 0 0" />
		<parent link="waist_yaw_link" />
		<child link="l_shoulder_pitch_link" />
		<axis xyz="0 1 0" />
		<limit lower="-3.14" upper="3.14" effort="21" velocity="21" />
	</joint>
	<link name="l_shoulder_roll_link">
		<inertial>
			<origin xyz="0.0130362074480209 -0.000693612202312968 -0.0440802542287992" rpy="0 0 0" />
			<mass value="0.0691228339416344" />
			<inertia ixx="1.49102417693405E-05" ixy="-8.50035544343878E-08" ixz="4.64698241784217E-07" iyy="1.45677424509261E-05" iyz="-1.41930266401131E-08" izz="1.81326426567256E-05" />
		</inertial>
		<visual>
			<origin xyz="0 0 0" rpy="0 0 0" />
			<geometry>
				<mesh filename="package://hi_1_18_240815/meshes/l_shoulder_roll_link.STL" />
			</geometry>
			<material name="">
				<color rgba="0.898039215686275 0.917647058823529 0.929411764705882 1" />
			</material>
		</visual>
		<collision>
			<origin xyz="0 0 0" rpy="0 0 0" />
			<geometry>
				<mesh filename="package://hi_1_18_240815/meshes/l_shoulder_roll_link.STL" />
			</geometry>
		</collision>
	</link>
	<joint name="l_shoulder_roll_joint" type="fixed">
		<origin xyz="-0.0233999999999998 0.0509999999999989 0" rpy="0 0 0" />
		<parent link="l_shoulder_pitch_link" />
		<child link="l_shoulder_roll_link" />
		<axis xyz="-1 0 0" />
		<limit lower="-3.14" upper="3.14" effort="21" velocity="21" />
	</joint>
	<link name="l_elbow_yaw_link">
		<inertial>
			<origin xyz="-0.00764931602992031 -0.000602918378956735 -0.0427156652301165" rpy="0 0 0" />
			<mass value="0.0626286053112173" />
			<inertia ixx="2.37234482179663E-05" ixy="-1.28582574711363E-09" ixz="2.60518309152138E-09" iyy="1.59921558791952E-05" iyz="8.50114107528992E-08" izz="1.03716046932082E-05" />
		</inertial>
		<visual>
			<origin xyz="0 0 0" rpy="0 0 0" />
			<geometry>
				<mesh filename="package://hi_1_18_240815/meshes/l_elbow_yaw_link.STL" />
			</geometry>
			<material name="">
				<color rgba="0.792156862745098 0.819607843137255 0.933333333333333 1" />
			</material>
		</visual>
		<collision>
			<origin xyz="0 0 0" rpy="0 0 0" />
			<geometry>
				<mesh filename="package://hi_1_18_240815/meshes/l_elbow_yaw_link.STL" />
			</geometry>
		</collision>
	</link>
	<joint name="l_elbow_yaw_joint" type="fixed">
		<origin xyz="0.0234000000000008 0 -0.086699999999999" rpy="0 0 0" />
		<parent link="l_shoulder_roll_link" />
		<child link="l_elbow_yaw_link" />
		<axis xyz="0 0 -1" />
		<limit lower="-3.14" upper="3.14" effort="21" velocity="21" />
	</joint>
	<link name="l_elbow_roll_link">
		<inertial>
			<origin xyz="-0.0109740689676518 -0.0023875703845927 -0.0442266231471097" rpy="0 0 0" />
			<mass value="0.0594041571445669" />
			<inertia ixx="1.35448907928459E-05" ixy="-8.50035544345788E-08" ixz="-4.73675721714161E-07" iyy="1.23966009673565E-05" iyz="-1.41832416010153E-08" izz="1.46319337570601E-05" />
		</inertial>
		<visual>
			<origin xyz="0 0 0" rpy="0 0 0" />
			<geometry>
				<mesh filename="package://hi_1_18_240815/meshes/l_elbow_roll_link.STL" />
			</geometry>
			<material name="">
				<color rgba="0.792156862745098 0.819607843137255 0.933333333333333 1" />
			</material>
		</visual>
		<collision>
			<origin xyz="0 0 0" rpy="0 0 0" />
			<geometry>
				<mesh filename="package://hi_1_18_240815/meshes/l_elbow_roll_link.STL" />
			</geometry>
		</collision>
	</link>
	<joint name="l_elbow_roll_joint" type="fixed">
		<origin xyz="0.0225 0 -0.0501" rpy="0 0 0" />
		<parent link="l_elbow_yaw_link" />
		<child link="l_elbow_roll_link" />
		<axis xyz="1 0 0" />
		<limit lower="-3.14" upper="3.14" effort="21" velocity="21" />
	</joint>
</robot>
